Workbook
Name EEZ_area: 'Offshore EEZ zones'!#REF!
Name ETRI_off: #REF!
Name ETRI_off: #REF!
Name ETRI_off: #REF!
Name ETRI_off: #REF!
Name ETRI_off: #REF!
Name ETRI_on: #REF!
Name ETRI_on: #REF!
Name ETRI_on: #REF!
Name ETRI_on: #REF!
Name ETRI_on: #REF!
Name markups: #REF!
Name markups: #REF!
Name markups: #REF!
Name markups: #REF!
Name markups: #REF!
Name SEA_DEPTH_00_30_DIST_050_200: 'Offshore EEZ Pivot'!#REF!

Sheet Context
B12: ENSPRESO - Wind onshore and offshore
B15: ENSPRESO
B16: ENSPRESO is an EU-28 wide, open dataset for energy models on renewable energy potentials,
B17: at national (NUTS0) and regional levels (NUTS2) for the 2010-2050 period.
B18: Within ENSPRESO, ENergy Systems Potential Renewable Energy SOurces, technical potentials are provided
B19: for wind, solar and biomass, based on coherent GIS-based land-restriction scenarios.
B21: Open access journal describing ENSPRESO:
B22: https://www.sciencedirect.com/science/article/pii/S2211467X19300720
B24: Data are in line with following JRC report:
B25: Wind potentials for EU and neighbouring countries, 2018, JRC109698
B26: https://ec.europa.eu/jrc/en/publication/wind-potentials-eu-and-neighbouring-countries-input-datasets-jrc-eu-times-model
B27: Capacity Factors from non-EU countries have not been verified
... B48: Version log
B49: 43651 | C49: Added Luxembourg
C50: Improved scenario explanation
C51: Introduced adjustable power density of the wind farm in the sheet "Raw data"
B52: 43665 | C52: Further disaggregation offshore scenario "EU-Wide low restrictions"; separating 12nm zones
C53: Included deeper waters (100-1000m) for scenario "EU-Wide low restrictions"
C54: Introduced sheet "OFFSHORE GIS output example"
C55: Introduced sheet with pivot "Wind Potential Pivot Countries"
C56: Update of the comparison of ENSPRESO wind with other sources; also introducing total numbers under a 10 MW/km2 assumption for the power density of the wind farm
C57: Update on offshore scenarios definition - Table 4 of the report "Wind potentials for EU and neighbouring countries, 2018, JRC109698"
B58: 43901 | C58: Additions in the sheet “ONSHORE SUMMARY + graph” : Capacity factors > 20%, median of all surfaces and Top-10
C59: Additions in the sheet “OFFSHORE SUMMARY + graph”: Capacity factors Top-10
B60: 44033 | C60: Offshore potential now split by sea basin and for the EU-27, see sheet "OFFSHORE by sea basin EU27"
B63: Planned future updates
C64: The conversion of available land to power data is in this Excel based on a turbine with a hub height of 100m and a specific power of 300 W/m2
C65: In a future release, we also will include the data for a wind turbine with a specific power of 240 W/m2 that reaches higher capacity factors
C66: Also, we plan to release the GIS files on land use

Sheet Scenario definitions
B2: Technical potential
B3: The technical potential is an upper limit of the power that can be produced in a certain region with a chosen technology and given land use and other restrictions. Technical potentials can vary largely from having different assumptions regarding restrictions. All assumptions regarding restrictions are given in this sheet. Another important assumption for the technical potential is the power density of the wind farms. For ENSPRESO, 5 MW/km2 was assumed. Since the technical potential (either GW or TWh) is proportional to the suitable areas, the ENSPRESO potential can easily be adjusted for different power densities of the wind farms. As an example, the Belgian wind offshore ENSPRESO potential is 1.9 GW with 5 MW/km2 and 3.8 GW when 10 MW/km2 is assumed.
B5: OFFSHORE | D5: EU-Wide high restrictions | F5: Reference - Large turbines scenario | H5: EU-Wide low restrictions
C6: description --> | D6: A hypothetical scenario with a high level of exclusion of surfaces for wind | F6: A scenario with average buffers around offshore exclusion zones | H6: A hypothetical scenario with a low level of exclusion of surfaces for wind
C7: Distance to shore --> | D7: >12 nm | F7: >12 nm | H7: 0-12 nm (0-22 km) and 22-200 km
C8: Inland waters --> | D8: no | F8: no | H8: as part of 0-12 nm category
C9: Sea depth --> | D9: 0-100 m | F9: 0-100 m | H9: 0-1000 m (report only covers 0-100 m)
C10: Shipping density (ships per year) --> | D10: < 500 | F10: < 1000 | H10: < 5000
C11: Distance to shipping lanes --> | D11: > 4 nm | F11: > 2 nm | H11: > 2 nm
C12: Distance to gas & oil pipelines --> | D12: > 4 nm | F12: > 2 nm | H12: > 2 nm
C13: Distance to oil and gas wells --> | D13: > 4 nm | F13: > 2 nm | H13: > 2 nm
C14: Submarine cables --> | D14: > 4 nm | F14: > 2 nm | H14: > 2 nm
B18: ONSHORE | D18: EU-Wide high restrictions | F18: Reference - Large turbines scenario | H18: EU-Wide low restrictions
C19: description --> | D19: A hypothetical scenario in which the exclusion of surfaces for wind converges in all countries to a high level. | F19: Current legal requirements for exclusion zones and setback distances. | H19: A hypothetical scenario in which the exclusion of surfaces for wind converges in all countries to a low level.
C20: disclaimer --> | F20: Given some strict exclusions (i.e. in some provinces of Austria) the potential for large turbines in the Reference - Large turbines scenario may be smaller than the current installed capacity. For those regions we advice to use one of the other scenarios.
C21: driver --> | D21: min allowed distance from settlements | F21: min allowed distance from settlements | H21: min allowed distance from settlements
C22: year --> | D22: 2030 onwards | F22: 2016 onwards | H22: 2030 onwards
D23: Small turbines | E23: Big turbines | F23: Small turbines | G23: Big turbines | H23: Small turbines | I23: Big turbines
E24: (not used in the summary numbers) | F24: (not used in the summary numbers) | H24: (not used in the summary numbers)
C25: unit --> | D25: [m] | E25: [m] | F25: [m] | G25: [m] | H25: [m] | I25: [m]
B26: Country | C26: Subcountry level
B27: Austria | C27: Niederösterreich | D27: 1200 | E27: 2000 | F27: 1200 | G27: 1200 | H27: 120 | I27: 400
B28: Austria | C28: Oberösterreich | D28: 1200 | E28: 2000 | F28: 800 | G28: 800 | H28: 120 | I28: 400
B29: Austria | C29: Steiermark | D29: 1200 | E29: 2000 | F29: 1000 | G29: 1000 | H29: 120 | I29: 400
B30: Austria | C30: Burgenland | D30: 1200 | E30: 2000 | F30: 1000 | G30: 1000 | H30: 120 | I30: 400
B31: Austria | C31: Vorarlberg | D31: 1200 | E31: 2000 | F31: Not allowed | G31: Not allowed | H31: 120 | I31: 400
B32: Austria | C32: Tyrol | D32: 1200 | E32: 2000 | F32: Not allowed | G32: Not allowed | H32: 120 | I32: 400
B33: Austria | C33: Salzburg | D33: 1200 | E33: 2000 | F33: Not allowed | G33: Not allowed | H33: 120 | I33: 400
B34: Austria | C34: Carinthia | D34: 1200 | E34: 2000 | F34: Not allowed | G34: Not allowed | H34: 120 | I34: 400
B35: Austria | C35: Vienna | D35: 1200 | E35: 2000 | F35: Not allowed | G35: Not allowed | H35: 120 | I35: 400
B36: Belgium | C36: Flanders | D36: 1200 | E36: 2000 | F36: 600 | G36: 600 | H36: 120 | I36: 400
B37: Belgium | C37: Wallonia | D37: 1200 | E37: 2000 | F37: 400 | G37: 400 | H37: 120 | I37: 400
B38: Belgium | C38: Brussels | D38: 1200 | E38: 2000 | F38: Not allowed | G38: Not allowed | H38: 120 | I38: 400
B39: Bulgaria | C39: all | D39: 1200 | E39: 2000 | F39: 120 | G39: 500 | H39: 120 | I39: 400
B40: Croatia | C40: all | D40: 1200 | E40: 2000 | F40: 500 | G40: 500 | H40: 120 | I40: 400
B41: Cyprus | C41: all | D41: 1200 | E41: 2000 | F41: 850 | G41: 850 | H41: 120 | I41: 400
B42: Czech Republic | C42: all | D42: 1200 | E42: 2000 | F42: 120 | G42: 500 | H42: 120 | I42: 400
B43: Denmark | C43: all | D43: 1200 | E43: 2000 | F43: 600 | G43: 600 | H43: 120 | I43: 400
B44: Estonia | C44: all | D44: 1200 | E44: 2000 | F44: 1000 | G44: 1000 | H44: 120 | I44: 400
B45: Finland | C45: all | D45: 1200 | E45: 2000 | F45: 1000 | G45: 1000 | H45: 120 | I45: 400
...

Sheet Exclusion of land
B1: Landcover data based on LUISA
A2: LUISA | C2: Source | D2: Wind high | E2: Wind low | F2: Wind ref
A3: Class # | B3: Class Description | D3: usable | E3: Usable | F3: Usable
A4: 1 | B4: Urban | D4: no | E4: no | F4: no
A5: 2 | B5: Industry | D5: no | E5: no | F5: no
A6: 3 | B6: Other Arable | D6: yes | E6: yes | F6: yes
A7: 4 | B7: Permanent Crops | D7: yes | E7: yes | F7: yes
A8: 5 | B8: Pastures | D8: yes | E8: yes | F8: yes
A9: 6 | B9: Forests | D9: no | E9: no | F9: no
A10: 7 | B10: Transitional woodland-shrub | D10: no | E10: no | F10: no
A11: 8 | B11: Cereals | D11: yes | E11: yes | F11: yes
A12: 9 | B12: Maize | D12: yes | E12: yes | F12: yes
A13: 10 | B13: Root crops | D13: yes | E13: yes | F13: yes
A14: 11 | B14: Abandoned Arable Land | D14: yes | E14: yes | F14: yes
A15: 12 | B15: Abandoned Permanent Crops | D15: yes | E15: yes | F15: yes
... A25: 22 | B25: Urban green leisure | D25: no | E25: no | F25: no
B26: DNI > 1800 kWh/am² | D26: N/A | E26: N/A | F26: N/A
B28: Additional Criteria: | C28: Source
B29: Protected Areas | C29: WDPA[3] | D29: no | E29: no | F29: no
B30: Geomorphology | C30: DSMW [4] | D30: no | E30: no | F30: no
B31: Slope <2.1° | C31: Globe [5] | D31: no | E31: no | F31: no
B32: Distance to Settlements | C32: Luisa | D32: MS - specific values | E32: MS - specific values | F32: MS - specific values
B35: Offshore data
B36: Sea depth | C36: GEBCO [6] | N36: < 100m | O36: <50m | P36: <50m
B37: Shipping density (ships per year) | C37: Globalmarin [7] | N37: <500 | O37: <5000 | P37: <1000
B38: Distance to shipping lanes | C38: Globalmarin [7] | N38: 2nm | O38: 4nm | P38: 2nm
B39: Distance to gas & oil pipelines | C39: World Energy Atlas [8] | N39: 2nm | O39: 4nm | P39: 2nm
B40: Distance to oil and gas wells | C40: World Energy Atlas [8] | N40: 2nm | O40: 4nm | P40: 2nm
B41: Minumum distance to shore | N41: 12nm | O41: 12nm | P41: 12nm
B42: Maximum distance to shore
B43: submarine cables | C43: Gregs Cablemap [9]
N44: 2nm | O44: 4nm | P44: 2nm
B46: Data sources | C46: Name | D46: Note | I46: Public | J46: Link
B47: 1 | C47: Global Land Cover | D47: Reclassified for REMix, Different Set of Classes possbile. | I47: Yes | J47: http://geoserver.isciences.com:8080/geonetwork/srv/en/metadata.show?id=228&currTab=simple
B48: 2 | C48: CORINE | I48: Yes | J48: http://www.eea.europa.eu/data-and-maps/data/corine-land-cover-2006-raster-3
B49: 3 | C49: World Data of Protected Areas 2010 | I49: Yes | J49: http://www.wdpa.org/
B50: 4 | C50: DSMW (Digital Soil Map of the World) | D50: The Global Land One-kilometer Base Elevation (GLOBE) Digital Elevation Model V1.0 | I50: Yes | J50: http://www.fao.org/geonetwork/srv/en/metadata.show?id=14116
B51: 5 | C51: Globe | D51: General Bathymetric Chart of the Oceans (GEBCO) Digital Atlas | I51: Yes | J51: http://www.ngdc.noaa.gov/mgg/topo/globe.html
B52: 6 | C52: GEBCO | I52: yes
B53: 7 | D53: Global Map of Marine Impact | I53: yes | J53: https://www.nceas.ucsb.edu/globalmarine
...

Sheet Wind Potential EU28 Full
A1: Country | B1: NUTS2 Region | C1: Onshore Offshore | D1: Offshore categories | E1: Hub height (m) | F1: Scenario | G1: Wind condition | H1: Measure | I1: Unit | J1: Value
A2: Belgium | B2: EZBE | C2: Offshore | D2: Water depth 0-30m | E2: 100 | F2: EU-Wide high restrictions | G2: 15%< CF<20% | H2: Potential capacity | I2: GWe | J2: 0
A3: Bulgaria | B3: EZBG | C3: Offshore | D3: Water depth 0-30m | E3: 100 | F3: EU-Wide high restrictions | G3: 15%< CF<20% | H3: Potential capacity | I3: GWe | J3: 0
A4: Croatia | B4: EZHR | C4: Offshore | D4: Water depth 0-30m | E4: 100 | F4: EU-Wide high restrictions | G4: 15%< CF<20% | H4: Potential capacity | I4: GWe | J4: 0
A5: Cyprus | B5: EZCY | C5: Offshore | D5: Water depth 0-30m | E5: 100 | F5: EU-Wide high restrictions | G5: 15%< CF<20% | H5: Potential capacity | I5: GWe | J5: 0
A6: Denmark | B6: EZDK | C6: Offshore | D6: Water depth 0-30m | E6: 100 | F6: EU-Wide high restrictions | G6: 15%< CF<20% | H6: Potential capacity | I6: GWe | J6: 0
A7: Estonia | B7: EZEE | C7: Offshore | D7: Water depth 0-30m | E7: 100 | F7: EU-Wide high restrictions | G7: 15%< CF<20% | H7: Potential capacity | I7: GWe | J7: 0
A8: Finland | B8: EZFI | C8: Offshore | D8: Water depth 0-30m | E8: 100 | F8: EU-Wide high restrictions | G8: 15%< CF<20% | H8: Potential capacity | I8: GWe | J8: 0
A9: France | B9: EZFR | C9: Offshore | D9: Water depth 0-30m | E9: 100 | F9: EU-Wide high restrictions | G9: 15%< CF<20% | H9: Potential capacity | I9: GWe | J9: 0
A10: Germany | B10: EZDE | C10: Offshore | D10: Water depth 0-30m | E10: 100 | F10: EU-Wide high restrictions | G10: 15%< CF<20% | H10: Potential capacity | I10: GWe | J10: 0
A11: Greece | B11: EZGR | C11: Offshore | D11: Water depth 0-30m | E11: 100 | F11: EU-Wide high restrictions | G11: 15%< CF<20% | H11: Potential capacity | I11: GWe | J11: 0
A12: Ireland | B12: EZIR | C12: Offshore | D12: Water depth 0-30m | E12: 100 | F12: EU-Wide high restrictions | G12: 15%< CF<20% | H12: Potential capacity | I12: GWe | J12: 0
A13: Italy | B13: EZIT | C13: Offshore | D13: Water depth 0-30m | E13: 100 | F13: EU-Wide high restrictions | G13: 15%< CF<20% | H13: Potential capacity | I13: GWe | J13: 0.008
... A793: United Kingdom | B793: EZUK | C793: Offshore | D793: Water depth 60-100m Floating | E793: 100 | F793: Reference - Large turbines | G793: CF > 25% | H793: Potential production | I793: TWh | J793: 0
A794: Austria | B794: AT11 | C794: Onshore | E794: 100 | F794: EU-Wide high restrictions | G794: 15%< CF<20% | H794: Potential capacity | I794: GWe | J794: 0.25171254
A795: Austria | B795: AT12 | C795: Onshore | E795: 100 | F795: EU-Wide high restrictions | G795: 15%< CF<20% | H795: Potential capacity | I795: GWe | J795: 0
A796: Austria | B796: AT13 | C796: Onshore | E796: 100 | F796: EU-Wide high restrictions | G796: 15%< CF<20% | H796: Potential capacity | I796: GWe | J796: 0
A797: Austria | B797: AT21 | C797: Onshore | E797: 100 | F797: EU-Wide high restrictions | G797: 15%< CF<20% | H797: Potential capacity | I797: GWe | J797: 0.57769407
A798: Austria | B798: AT22 | C798: Onshore | E798: 100 | F798: EU-Wide high restrictions | G798: 15%< CF<20% | H798: Potential capacity | I798: GWe | J798: 1.1529613
A799: Austria | B799: AT31 | C799: Onshore | E799: 100 | F799: EU-Wide high restrictions | G799: 15%< CF<20% | H799: Potential capacity | I799: GWe | J799: 1.2568192
A800: Austria | B800: AT32 | C800: Onshore | E800: 100 | F800: EU-Wide high restrictions | G800: 15%< CF<20% | H800: Potential capacity | I800: GWe | J800: 0.51280277
A801: Austria | B801: AT33 | C801: Onshore | E801: 100 | F801: EU-Wide high restrictions | G801: 15%< CF<20% | H801: Potential capacity | I801: GWe | J801: 1.310112
A802: Austria | B802: AT34 | C802: Onshore | E802: 100 | F802: EU-Wide high restrictions | G802: 15%< CF<20% | H802: Potential capacity | I802: GWe | J802: 0.31689612
A803: Belgium | B803: BE10 | C803: Onshore | E803: 100 | F803: EU-Wide high restrictions | G803: 15%< CF<20% | H803: Potential capacity | I803: GWe | J803: 0
A804: Belgium | B804: BE21 | C804: Onshore | E804: 100 | F804: EU-Wide high restrictions | G804: 15%< CF<20% | H804: Potential capacity | I804: GWe | J804: 0
A805: Belgium | B805: BE22 | C805: Onshore | E805: 100 | F805: EU-Wide high restrictions | G805: 15%< CF<20% | H805: Potential capacity | I805: GWe | J805: 0
... A5617: United Kingdom | B5617: UKN0 | C5617: Onshore | E5617: 100 | F5617: Reference - Large turbines | G5617: CF > 25% | H5617: Potential production | I5617: TWh | J5617: 97.425549
A5618: Belgium | B5618: EZBE | C5618: Offshore | D5618: 12nm zone, water depth 0-30m | E5618: 100 | F5618: EU-Wide low restrictions | G5618: 15%< CF<20% | H5618: Potential capacity | I5618: GWe | J5618: 0
A5619: Bulgaria | B5619: EZBG | C5619: Offshore | D5619: 12nm zone, water depth 0-30m | E5619: 100 | F5619: EU-Wide low restrictions | G5619: 15%< CF<20% | H5619: Potential capacity | I5619: GWe | J5619: 0
A5620: Cyprus | B5620: EZCY | C5620: Offshore | D5620: 12nm zone, water depth 0-30m | E5620: 100 | F5620: EU-Wide low restrictions | G5620: 15%< CF<20% | H5620: Potential capacity | I5620: GWe | J5620: 0.78678261
A5621: Germany | B5621: EZDE | C5621: Offshore | D5621: 12nm zone, water depth 0-30m | E5621: 100 | F5621: EU-Wide low restrictions | G5621: 15%< CF<20% | H5621: Potential capacity | I5621: GWe | J5621: 0
A5622: Denmark | B5622: EZDK | C5622: Offshore | D5622: 12nm zone, water depth 0-30m | E5622: 100 | F5622: EU-Wide low restrictions | G5622: 15%< CF<20% | H5622: Potential capacity | I5622: GWe | J5622: 0
A5623: Estonia | B5623: EZEE | C5623: Offshore | D5623: 12nm zone, water depth 0-30m | E5623: 100 | F5623: EU-Wide low restrictions | G5623: 15%< CF<20% | H5623: Potential capacity | I5623: GWe | J5623: 0
A5624: Greece | B5624: EZGR | C5624: Offshore | D5624: 12nm zone, water depth 0-30m | E5624: 100 | F5624: EU-Wide low restrictions | G5624: 15%< CF<20% | H5624: Potential capacity | I5624: GWe | J5624: 0
A5625: Spain | B5625: EZES | C5625: Offshore | D5625: 12nm zone, water depth 0-30m | E5625: 100 | F5625: EU-Wide low restrictions | G5625: 15%< CF<20% | H5625: Potential capacity | I5625: GWe | J5625: 0
A5626: Finland | B5626: EZFI | C5626: Offshore | D5626: 12nm zone, water depth 0-30m | E5626: 100 | F5626: EU-Wide low restrictions | G5626: 15%< CF<20% | H5626: Potential capacity | I5626: GWe | J5626: 0
A5627: France | B5627: EZFR | C5627: Offshore | D5627: 12nm zone, water depth 0-30m | E5627: 100 | F5627: EU-Wide low restrictions | G5627: 15%< CF<20% | H5627: Potential capacity | I5627: GWe | J5627: 0
A5628: Croatia | B5628: EZHR | C5628: Offshore | D5628: 12nm zone, water depth 0-30m | E5628: 100 | F5628: EU-Wide low restrictions | G5628: 15%< CF<20% | H5628: Potential capacity | I5628: GWe | J5628: 0
A5629: Ireland | B5629: EZIR | C5629: Offshore | D5629: 12nm zone, water depth 0-30m | E5629: 100 | F5629: EU-Wide low restrictions | G5629: 15%< CF<20% | H5629: Potential capacity | I5629: GWe | J5629: 0
... A6541: United Kingdom | B6541: EZUK | C6541: Offshore | D6541: Water depth 60-100m Floating | E6541: 100 | F6541: EU-Wide low restrictions | G6541: CF > 25% | H6541: Potential production | I6541: TWh | J6541: 1926.8909

Sheet Wind Potential Pivot EU
A2: Measure | B2: Potential capacity
A3: Country | B3: (All)
A5: Sum of Value | B5: Column Labels
A6: Row Labels | B6: 15%< CF<20% | C6: 20% < CF < 25% | D6: CF > 25% | E6: Grand Total
A7: EU-Wide high restrictions
A8: Offshore | B8: 0.118 | C8: 0.734 | D8: 80.043 | E8: 80.895
A9: Water depth 30-60m | B9: 0.11 | C9: 0.705 | D9: 55.381 | E9: 56.196
A10: Water depth 0-30m | B10: 0.008 | C10: 0.029 | D10: 24.662 | E10: 24.699
A11: Water depth 60-100m Floating | B11: 0 | C11: 0 | D11: 0 | E11: 0
A12: Onshore | B12: 854.94656 | C12: 850.89689 | D12: 1185.1939 | E12: 2891.0373
A13: (blank) | B13: 854.94656 | C13: 850.89689 | D13: 1185.1939 | E13: 2891.0373
A14: Reference - Large turbines
A15: Offshore | B15: 0.73 | C15: 5.473 | D15: 324.171 | E15: 330.374
A16: Water depth 30-60m | B16: 0.641 | C16: 5.206 | D16: 227.567 | E16: 233.414
A17: Water depth 0-30m | B17: 0.089 | C17: 0.267 | D17: 96.604 | E17: 96.96
A18: Water depth 60-100m Floating | B18: 0 | C18: 0 | D18: 0 | E18: 0
A19: Onshore | B19: 1289.7271 | C19: 1353.2748 | D19: 2067.1147 | E19: 4710.1166
A20: (blank) | B20: 1289.7271 | C20: 1353.2748 | D20: 2067.1147 | E20: 4710.1166
A21: EU-Wide low restrictions
A22: Offshore | B22: 89.223911 | C22: 474.07937 | D22: 6597.7717 | E22: 7161.075
A23: Water depth 30-60m | B23: 2.5298823 | C23: 20.959794 | D23: 611.74532 | E23: 635.235
A24: Water depth 0-30m | B24: 0.38271658 | C24: 1.3498362 | D24: 175.75245 | E24: 177.485
A25: Water depth 60-100m Floating | B25: 2.9790802 | C25: 24.114394 | D25: 1009.6615 | E25: 1036.755
A26: Water depth 100-1000m Floating | B26: 55.526572 | C26: 242.87447 | D26: 3024.254 | E26: 3322.655
A27: 12nm zone, water depth 0-30m | B27: 10.954706 | C27: 50.370438 | D27: 721.37986 | E27: 782.705
A28: 12nm zone, water depth 30-60m | B28: 7.532319 | C28: 58.648844 | D28: 546.79484 | E28: 612.976
A29: 12nm zone, water depth 60-100m Floating | B29: 9.3186351 | C29: 75.761592 | D29: 508.18377 | E29: 593.264
A30: Onshore | B30: 1589.0289 | C30: 1790.8567 | D30: 2967.8256 | E30: 6347.7112
A31: (blank) | B31: 1589.0289 | C31: 1790.8567 | D31: 2967.8256 | E31: 6347.7112
A32: Grand Total | B32: 3823.7745 | C32: 4475.3148 | D32: 13222.12 | E32: 21521.209

Sheet Wind Potential Pivot Countries
A1: Measure | B1: Potential capacity
A2: Onshore Offshore | B2: Offshore
A3: Wind condition | B3: CF > 25%
A4: Scenario | B4: EU-Wide low restrictions
A6: Sum of Value | B6: Column Labels
A7: Row Labels | B7: Water depth 100-1000m Floating | C7: Water depth 60-100m Floating | D7: Water depth 30-60m | E7: Water depth 0-30m | F7: 12nm zone, water depth 60-100m Floating | G7: 12nm zone, water depth 30-60m | H7: 12nm zone, water depth 0-30m
A8: Belgium | B8: 0 | C8: 0 | D8: 0.145 | E8: 0.165 | F8: 0 | G8: 0.001 | H8: 1.541
A9: Bulgaria | B9: 26.97 | C9: 11.47 | D9: 1.33 | E9: 0 | F9: 3.427 | G9: 12.467 | H9: 6.72
A10: Croatia | B10: 20.205118 | C10: 7.2270098 | D10: 8.6361814 | E10: 0.18687255 | F10: 12.862933 | G10: 12.890774 | H10: 6.0893755
A11: Cyprus | B11: 5.4669559 | C11: 0 | D11: 0 | E11: 0 | F11: 0.29841176 | G11: 0.27485294 | H11: 0.267
A12: Denmark | B12: 9.41 | C12: 18.555 | D12: 81.25 | E12: 28.99 | F12: 4.979 | G12: 7.848 | H12: 84.368
A13: Estonia | B13: 8.39 | C13: 6.455 | D13: 7.245 | E13: 0.975 | F13: 8.614 | G13: 12.931 | H13: 17.604
A14: Finland | B14: 53 | C14: 68.445 | D14: 33.475 | E14: 8.51 | F14: 3.226 | G14: 29.974 | H14: 96.222
A15: France | B15: 405.065 | C15: 86.925 | D15: 42.55 | E15: 2.525 | F15: 44.511 | G15: 56.578 | H15: 98.086
A16: Germany | B16: 0 | C16: 0 | D16: 53.03 | E16: 27.18 | F16: 0 | G16: 0.018 | H16: 25.395
A17: Greece | B17: 105.54179 | C17: 2.2371702 | D17: 0.014622028 | E17: 0.0036555069 | F17: 58.393067 | G17: 32.972672 | H17: 20.705522
A18: Ireland | B18: 592.435 | C18: 98.055 | D18: 5.13 | E18: 0 | F18: 59.894 | G18: 45.463 | H18: 26.705
A19: Italy | B19: 184.06244 | C19: 13.911241 | D19: 11.813647 | E19: 1.7871497 | F19: 39.40847 | G19: 31.391187 | H19: 47.480569
... A29: United Kingdom | B29: 968.245 | C29: 452.515 | D29: 128.7 | E29: 62.115 | F29: 153.544 | G29: 146.31 | H29: 96.499

Sheet ONSHORE SUMMARY + graph
U3: EU-Wide high restrictions | X3: Reference - Large turbines | AA3: EU-Wide low restrictions | AF3: Average for all scenarios
T4: [GW] | U4: CF > 25% | V4: 20% < CF < 25% | W4: 15%< CF<20% | X4: CF > 25% | Y4: 20% < CF < 25% | Z4: 15%< CF<20% | AA4: CF > 25% | AB4: 20% < CF < 25% | AC4: 15%< CF<20% | AF4: CF > 25% | AG4: 20% < CF < 25% | AH4: 15%< CF<20% | AJ4: CF > 20% | AK4: Median of all surfaces | AL4: Top 10%
T5: Austria | U5: 17.179824 | V5: 7.2360512 | W5: 5.378998 | X5: 5.9277312 | Y5: 5.1208293 | Z5: 3.9883033 | AA5: 44.268823 | AB5: 17.909352 | AC5: 11.11148 | AF5: 0.2968 | AG5: 0.225 | AH5: 0.175 | AJ5: =SUMPRODUCT(AA5:AB5,$AF5:$AG5)/SUM(AA5:AB5) -> 0.27611925 | AK5: 0.2124213 | AL5: 0.34401389 | AM5: Austria
T6: Belgium | U6: 0.11368723 | V6: 0.30952044 | W6: 0.59600556 | X6: 2.1997292 | Y6: 5.9299602 | Z6: 10.336845 | AA6: 5.3180606 | AB6: 8.0376825 | AC6: 10.764348 | AF6: 0.3056 | AG6: 0.225 | AH6: 0.175 | AJ6: =SUMPRODUCT(AA6:AB6,$AF6:$AG6)/SUM(AA6:AB6) -> 0.25709374 | AK6: 0.21501941 | AL6: 0.2374375 | AM6: Belgium
T7: Bulgaria | U7: 3.2910762 | V7: 25.759094 | W7: 58.751086 | X7: 6.2951872 | Y7: 46.682063 | Z7: 102.05156 | AA7: 6.8104612 | AB7: 50.390228 | AC7: 109.59838 | AF7: 0.2688 | AG7: 0.225 | AH7: 0.175 | AJ7: =SUMPRODUCT(AA7:AB7,$AF7:$AG7)/SUM(AA7:AB7) -> 0.23021494 | AK7: 0.16353646 | AL7: 0.23234375 | AM7: Bulgaria
T8: Croatia | U8: 3.4209288 | V8: 7.3302927 | W8: 11.533381 | X8: 6.9488545 | Y8: 17.359653 | Z8: 29.212676 | AA8: 7.8018576 | AB8: 19.800433 | AC8: 33.524342 | AF8: 0.3049 | AG8: 0.225 | AH8: 0.175 | AJ8: =SUMPRODUCT(AA8:AB8,$AF8:$AG8)/SUM(AA8:AB8) -> 0.24758394 | AK8: 0.19629687 | AL8: 0.27771875 | AM8: Croatia
T9: Cyprus | U9: 0 | V9: 1.237902 | W9: 2.8766974 | X9: 0 | Y9: 1.9376549 | Z9: 4.5028177 | AA9: 0 | AB9: 3.228098 | AC9: 7.5016129 | AF9: / | AG9: 0.225 | AH9: 0.175 | AJ9: =SUMPRODUCT(AA9:AB9,$AF9:$AG9)/SUM(AA9:AB9) -> 0.225 | AK9: 0.14786458 | AL9: 0.225 | AM9: Cyprus
T10: Czech Republic | U10: 5.5319514 | V10: 5.0663892 | W10: 2.6666594 | X10: 38.420576 | Y10: 37.784031 | Z10: 16.475393 | AA10: 48.341366 | AB10: 48.149911 | AC10: 20.558723 | AF10: 0.2763 | AG10: 0.225 | AH10: 0.175 | AJ10: =SUMPRODUCT(AA10:AB10,$AF10:$AG10)/SUM(AA10:AB10) -> 0.25070089 | AK10: 0.23332943 | AL10: 0.27850781 | AM10: Czech Republic
T11: Denmark | U11: 12.605 | V11: 0 | W11: 0 | X11: 54.67 | Y11: 0 | Z11: 0 | AA11: 83.005 | AB11: 0 | AC11: 0 | AF11: 0.3633 | AG11: 0.225 | AH11: 0.175 | AJ11: =SUMPRODUCT(AA11:AB11,$AF11:$AG11)/SUM(AA11:AB11) -> 0.3633 | AK11: 0.3655 | AL11: 0.43955625 | AM11: Denmark
T12: Estonia | U12: 17.325183 | V12: 5.704817 | W12: 0 | X12: 20.522405 | Y12: 6.7575948 | Z12: 0 | AA12: 34.533761 | AB12: 11.371239 | AC12: 0 | AF12: 0.2837 | AG12: 0.225 | AH12: 0.175 | AJ12: =SUMPRODUCT(AA12:AB12,$AF12:$AG12)/SUM(AA12:AB12) -> 0.26915928 | AK12: 0.26934375 | AL12: 0.3304375 | AM12: Estonia
T13: Finland | U13: 16.751105 | V13: 9.5528579 | W13: 0.45103677 | X13: 19.732289 | Y13: 11.033347 | Z13: 0.49436471 | AA13: 38.145841 | AB13: 19.814255 | AC13: 0.69490441 | AF13: 0.2883 | AG13: 0.225 | AH13: 0.175 | AJ13: =SUMPRODUCT(AA13:AB13,$AF13:$AG13)/SUM(AA13:AB13) -> 0.26666024 | AK13: 0.2807125 | AL13: 0.35859375 | AM13: Finland
T14: France | U14: 164.49584 | V14: 96.606025 | W14: 34.859176 | X14: 550.36595 | Y14: 262.4561 | Z14: 93.573121 | AA14: 645.55854 | AB14: 298.16697 | AC14: 107.43277 | AF14: 0.2946 | AG14: 0.225 | AH14: 0.175 | AJ14: =SUMPRODUCT(AA14:AB14,$AF14:$AG14)/SUM(AA14:AB14) -> 0.27261011 | AK14: 0.24927699 | AL14: 0.31757955 | AM14: France
T15: Germany | U15: 22.328357 | V15: 39.241815 | W15: 24.492399 | X15: 42.191125 | Y15: 64.7814 | Z15: 37.092487 | AA15: 116.37693 | AB15: 191.88907 | AC15: 154.25493 | AF15: 0.2936 | AG15: 0.225 | AH15: 0.175 | AJ15: =SUMPRODUCT(AA15:AB15,$AF15:$AG15)/SUM(AA15:AB15) -> 0.25089795 | AK15: 0.2021849 | AL15: 0.25259293 | AM15: Germany
T16: Greece | U16: 89.29754 | V16: 56.120735 | W16: 79.661129 | X16: 102.34441 | Y16: 66.070294 | Z16: 95.737994 | AA16: 104.35069 | AB16: 67.522546 | AC16: 98.04546 | AF16: 0.3254 | AG16: 0.225 | AH16: 0.175 | AJ16: =SUMPRODUCT(AA16:AB16,$AF16:$AG16)/SUM(AA16:AB16) -> 0.28595661 | AK16: 0.20870633 | AL16: 0.35358894 | AM16: Greece
T17: Hungary | U17: 9.6296503 | V17: 32.539532 | W17: 68.837849 | X17: 12.700798 | Y17: 40.376515 | Z17: 79.773288 | AA17: 26.064725 | AB17: 72.33029 | AC17: 121.28732 | AF17: 0.265 | AG17: 0.225 | AH17: 0.175 | AJ17: =SUMPRODUCT(AA17:AB17,$AF17:$AG17)/SUM(AA17:AB17) -> 0.23559595 | AK17: 0.19637277 | AL17: 0.23500446 | AM17: Hungary
T18: Ireland | U18: 70.9 | V18: 0 | W18: 0 | X18: 146.5 | Y18: 0 | Z18: 0 | AA18: 163.515 | AB18: 0 | AC18: 0 | AF18: 0.4466 | AG18: 0.225 | AH18: 0.175 | AJ18: =SUMPRODUCT(AA18:AB18,$AF18:$AG18)/SUM(AA18:AB18) -> 0.4466 | AK18: 0.45134115 | AL18: 0.50548438 | AM18: Ireland
T19: Italy | U19: 47.96027 | V19: 83.590697 | W19: 80.105827 | X19: 64.533586 | Y19: 113.77301 | Z19: 113.20277 | AA19: 81.116156 | AB19: 144.90503 | AC19: 150.0332 | AF19: 0.2795 | AG19: 0.225 | AH19: 0.175 | AJ19: =SUMPRODUCT(AA19:AB19,$AF19:$AG19)/SUM(AA19:AB19) -> 0.24455936 | AK19: 0.1519628 | AL19: 0.26561364 | AM19: Italy
T20: Latvia | U20: 38.459294 | V20: 12.420706 | W20: 0 | X20: 60.058632 | Y20: 19.396368 | Z20: 0 | AA20: 64.219765 | AB20: 20.740235 | AC20: 0 | AF20: 0.2939 | AG20: 0.225 | AH20: 0.175 | AJ20: =SUMPRODUCT(AA20:AB20,$AF20:$AG20)/SUM(AA20:AB20) -> 0.27708029 | AK20: 0.27625 | AL20: 0.34053125 | AM20: Latvia
T21: Lithuania | U21: 49.683875 | V21: 7.6211253 | W21: 0 | X21: 111.24575 | Y21: 17.064246 | Z21: 0 | AA21: 123.44455 | AB21: 18.935448 | AC21: 0 | AF21: 0.2968 | AG21: 0.225 | AH21: 0.175 | AJ21: =SUMPRODUCT(AA21:AB21,$AF21:$AG21)/SUM(AA21:AB21) -> 0.28725115 | AK21: 0.28873437 | AL21: 0.33946875 | AM21: Lithuania
T22: Luxembourg | U22: 0 | V22: 0.066252101 | W22: 0.1137479 | X22: 0 | Y22: 0.69380672 | Z22: 1.1911933 | AA22: 0 | AB22: 0.88520168 | AC22: 1.5197983 | AF22: / | AG22: 0.225 | AH22: 0.175 | AJ22: =SUMPRODUCT(AA22:AB22,$AF22:$AG22)/SUM(AA22:AB22) -> 0.225 | AK22: 0.193375 | AL22: 0.22578125 | AM22: Luxembourg
T23: Malta | U23: 0 | V23: 0 | W23: 0 | X23: 0.037723529 | Y23: 0.012276471 | Z23: 0 | AA23: 0.079219412 | AB23: 0.025780588 | AC23: 0 | AF23: 0.287 | AG23: 0.225 | AH23: 0.175 | AJ23: =SUMPRODUCT(AA23:AB23,$AF23:$AG23)/SUM(AA23:AB23) -> 0.27177718 | AK23: 0.26810417 | AL23: 0.32778125 | AM23: Malta
T24: Netherlands | U24: 3.5259476 | V24: 0.34405239 | W24: 0 | X24: 43.336126 | Y24: 5.5288741 | Z24: 0 | AA24: 43.346126 | AB24: 5.5338741 | AC24: 0 | AF24: 0.3222 | AG24: 0.225 | AH24: 0.175 | AJ24: =SUMPRODUCT(AA24:AB24,$AF24:$AG24)/SUM(AA24:AB24) -> 0.31119565 | AK24: 0.31338585 | AL24: 0.36749219 | AM24: Netherlands
T25: Poland | U25: 90.051494 | V25: 26.385494 | W25: 4.2856537 | X25: 78.771911 | Y25: 22.776482 | Z25: 3.7575008 | AA25: 369.96102 | AB25: 132.29193 | AC25: 20.868955 | AF25: 0.2834 | AG25: 0.225 | AH25: 0.175 | AJ25: =SUMPRODUCT(AA25:AB25,$AF25:$AG25)/SUM(AA25:AB25) -> 0.26801761 | AK25: 0.25394303 | AL25: 0.29776563 | AM25: Poland
T26: Portugal | U26: 2.8406587 | V26: 20.926157 | W26: 40.437312 | X26: 5.159804 | Y26: 34.029316 | Z26: 62.63976 | AA26: 5.6650539 | AB26: 36.981115 | AC26: 67.2926 | AF26: 0.2811 | AG26: 0.225 | AH26: 0.175 | AJ26: =SUMPRODUCT(AA26:AB26,$AF26:$AG26)/SUM(AA26:AB26) -> 0.23245224 | AK26: 0.19709375 | AL26: 0.24936875 | AM26: Portugal
T27: Romania | U27: 16.714075 | V27: 82.46376 | W27: 128.04345 | X27: 29.214643 | Y27: 139.65842 | Z27: 217.69716 | AA27: 31.682155 | AB27: 150.9194 | AC27: 235.46726 | AF27: 0.2638 | AG27: 0.225 | AH27: 0.175 | AJ27: =SUMPRODUCT(AA27:AB27,$AF27:$AG27)/SUM(AA27:AB27) -> 0.23173197 | AK27: 0.16814063 | AL27: 0.23183203 | AM27: Romania
T28: Slovakia | U28: 4.7722567 | V28: 5.0686223 | W28: 4.4019053 | X28: 14.168211 | Y28: 15.12425 | Z28: 15.904709 | AA28: 16.281671 | AB28: 17.389291 | AC28: 18.731234 | AF28: 0.2696 | AG28: 0.225 | AH28: 0.175 | AJ28: =SUMPRODUCT(AA28:AB28,$AF28:$AG28)/SUM(AA28:AB28) -> 0.24656643 | AK28: 0.19461458 | AL28: 0.25175 | AM28: Slovakia
T29: Slovenia | U29: 0.12029271 | V29: 0.80190971 | W29: 1.6831227 | X29: 0.36663376 | Y29: 2.0578956 | Z29: 4.3090214 | AA29: 0.45872387 | AB29: 2.4317124 | AC29: 5.0872315 | AF29: 0.2651 | AG29: 0.225 | AH29: 0.175 | AJ29: =SUMPRODUCT(AA29:AB29,$AF29:$AG29)/SUM(AA29:AB29) -> 0.23136403 | AK29: 0.12758854 | AL29: 0.24504688 | AM29: Slovenia
T30: Spain | U30: 244.26918 | V30: 291.03587 | W30: 302.41972 | X30: 321.44444 | Y30: 382.95874 | Z30: 393.91104 | AA30: 333.25628 | AB30: 397.37877 | AC30: 409.10704 | AF30: 0.281 | AG30: 0.225 | AH30: 0.175 | AJ30: =SUMPRODUCT(AA30:AB30,$AF30:$AG30)/SUM(AA30:AB30) -> 0.25054265 | AK30: 0.20270508 | AL30: 0.30523529 | AM30: Spain
T31: Sweden | U31: 100.26315 | V31: 21.230448 | W31: 3.3514027 | X31: 109.76137 | Y31: 24.103476 | Z31: 3.8751499 | AA31: 153.77241 | AB31: 37.890322 | AC31: 6.1472665 | AF31: 0.3406 | AG31: 0.225 | AH31: 0.175 | AJ31: =SUMPRODUCT(AA31:AB31,$AF31:$AG31)/SUM(AA31:AB31) -> 0.31774672 | AK31: 0.29209896 | AL31: 0.39916797 | AM31: Sweden
T32: United Kingdom | U32: 153.66324 | V32: 12.236763 | W32: 0 | X32: 220.19682 | Y32: 9.8081818 | Z32: 0 | AA32: 420.45143 | AB32: 15.938573 | AC32: 0 | AF32: 0.3734 | AG32: 0.225 | AH32: 0.175 | AJ32: =SUMPRODUCT(AA32:AB32,$AF32:$AG32)/SUM(AA32:AB32) -> 0.36797988 | AK32: 0.34230872 | AL32: 0.39672422 | AM32: United Kingdom
T33: EU28 | U33: =SUM(U5:U32) -> 1185.1939 | V33: =SUM(V5:V32) -> 850.89689 | W33: =SUM(W5:W32) -> 854.94656 | X33: =SUM(X5:X32) -> 2067.1147 | Y33: =SUM(Y5:Y32) -> 1353.2748 | Z33: =SUM(Z5:Z32) -> 1289.7271 | AA33: =SUM(AA5:AA32) -> 2967.8256 | AB33: =SUM(AB5:AB32) -> 1790.8567 | AC33: =SUM(AC5:AC32) -> 1589.0289

Sheet OFFSHORE SUMMARY + graph
U2: Table for offshore with capacity factor > 25%
U3: EU-Wide high restrictions | Y3: Reference - Large turbines | AC3: EU-Wide low restrictions
T4: [GW] | U4: Water depth 60-100m Floating | V4: Water depth 30-60m | W4: Water depth 0-30m | Y4: Water depth 60-100m Floating | Z4: Water depth 30-60m | AA4: Water depth 0-30m | AC4: Water depth 100-1000m Floating | AD4: Water depth 60-100m Floating | AE4: Water depth 30-60m | AF4: Water depth 0-30m | AG4: 12nm zone, water depth 60-100m Floating | AH4: 12nm zone, water depth 30-60m | AI4: 12nm zone, water depth 0-30m | AK4: CF > 25% | AL4: Top 10%
T5: Belgium | U5: 0 | V5: 0 | W5: 0 | Y5: 0 | Z5: 0.145 | AA5: 1.705 | AC5: 0 | AD5: 0 | AE5: 0.145 | AF5: 0.165 | AG5: 0 | AH5: 0.001 | AI5: 1.541 | AK5: 0.469 | AL5: ='CF Distribution Annual NUTS2'!I8 -> 0.4983125 | AM5: Belgium
T6: Bulgaria | U6: 0 | V6: 0 | W6: 0 | Y6: 0 | Z6: 0.435 | AA6: 0.01 | AC6: 26.97 | AD6: 11.47 | AE6: 1.33 | AF6: 0 | AG6: 3.427 | AH6: 12.467 | AI6: 6.72 | AK6: 0.337 | AL6: ='CF Distribution Annual NUTS2'!I9 -> 0.36125 | AM6: Bulgaria
T7: Croatia | U7: 0 | V7: 0.254 | W7: 0.004 | Y7: 0 | Z7: 2.082 | AA7: 0.004 | AC7: 20.205118 | AD7: 7.2270098 | AE7: 8.6361814 | AF7: 0.18687255 | AG7: 12.862933 | AH7: 12.890774 | AI7: 6.0893755 | AK7: 0.275 | AL7: ='CF Distribution Annual NUTS2'!I10 -> 0.28846875 | AM7: Croatia
T8: Cyprus | U8: 0 | V8: 0 | W8: 0 | Y8: 0 | Z8: 0 | AA8: 0 | AC8: 5.4669559 | AD8: 0 | AE8: 0 | AF8: 0 | AG8: 0.29841176 | AH8: 0.27485294 | AI8: 0.267 | AK8: 0.254 | AL8: ='CF Distribution Annual NUTS2'!I11 -> 0.2539375 | AM8: Cyprus
T9: Denmark | U9: 0 | V9: 0 | W9: 0 | Y9: 0 | Z9: 22.33 | AA9: 4.98 | AC9: 9.41 | AD9: 18.555 | AE9: 81.25 | AF9: 28.99 | AG9: 4.979 | AH9: 7.848 | AI9: 84.368 | AK9: 0.471 | AL9: ='CF Distribution Annual NUTS2'!I12 -> 0.52540625 | AM9: Denmark
T10: Estonia | U10: 0 | V10: 0.155 | W10: 0.025 | Y10: 0 | Z10: 1.2 | AA10: 0.08 | AC10: 8.39 | AD10: 6.455 | AE10: 7.245 | AF10: 0.975 | AG10: 8.614 | AH10: 12.931 | AI10: 17.604 | AK10: 0.458 | AL10: ='CF Distribution Annual NUTS2'!I13 -> 0.48715625 | AM10: Estonia
T11: Finland | U11: 0 | V11: 7.83 | W11: 5.79 | Y11: 0 | Z11: 15.065 | AA11: 6.2 | AC11: 53 | AD11: 68.445 | AE11: 33.475 | AF11: 8.51 | AG11: 3.226 | AH11: 29.974 | AI11: 96.222 | AK11: 0.454 | AL11: ='CF Distribution Annual NUTS2'!I14 -> 0.48875 | AM11: Finland
T12: France | U12: 0 | V12: 2.75 | W12: 0.555 | Y12: 0 | Z12: 13.9 | AA12: 1.745 | AC12: 405.065 | AD12: 86.925 | AE12: 42.55 | AF12: 2.525 | AG12: 44.511 | AH12: 56.578 | AI12: 98.086 | AK12: 0.418 | AL12: ='CF Distribution Annual NUTS2'!I15 -> 0.482375 | AM12: France
T13: Germany | U13: 0 | V13: 0 | W13: 1.08 | Y13: 0 | Z13: 17.55 | AA13: 10.29 | AC13: 0 | AD13: 0 | AE13: 53.03 | AF13: 27.18 | AG13: 0 | AH13: 0.018 | AI13: 25.395 | AK13: 0.437 | AL13: ='CF Distribution Annual NUTS2'!I16 -> 0.507875 | AM13: Germany
T14: Greece | U14: 0 | V14: 0 | W14: 0.004 | Y14: 0 | Z14: 0.007 | AA14: 0.011 | AC14: 105.54179 | AD14: 2.2371702 | AE14: 0.014622028 | AF14: 0.0036555069 | AG14: 58.393067 | AH14: 32.972672 | AI14: 20.705522 | AK14: 0.325 | AL14: ='CF Distribution Annual NUTS2'!I17 -> 0.422875 | AM14: Greece
T15: Ireland | U15: 0 | V15: 0.75 | W15: 0 | Y15: 0 | Z15: 0.99 | AA15: 0 | AC15: 592.435 | AD15: 98.055 | AE15: 5.13 | AF15: 0 | AG15: 59.894 | AH15: 45.463 | AI15: 26.705 | AK15: 0.527 | AL15: ='CF Distribution Annual NUTS2'!I18 -> 0.5578125 | AM15: Ireland
T16: Italy | U16: 0 | V16: 0.512 | W16: 0.039 | Y16: 0 | Z16: 2.995 | AA16: 0.414 | AC16: 184.06244 | AD16: 13.911241 | AE16: 11.813647 | AF16: 1.7871497 | AG16: 39.40847 | AH16: 31.391187 | AI16: 47.480569 | AK16: 0.291 | AL16: ='CF Distribution Annual NUTS2'!I19 -> 0.34 | AM16: Italy
T17: Latvia | U17: 0 | V17: 4.545 | W17: 0.18 | Y17: 0 | Z17: 12.77 | AA17: 2.2 | AC17: 40.225 | AD17: 16.28 | AE17: 32.285 | AF17: 4.05 | AG17: 0.055 | AH17: 15.081 | AI17: 25.568 | AK17: 0.464 | AL17: ='CF Distribution Annual NUTS2'!I21 -> 0.4876875 | AM17: Latvia
T18: Lithuania | U18: 0 | V18: 0.33 | W18: 0 | Y18: 0 | Z18: 2.555 | AA18: 0.385 | AC18: 0.095 | AD18: 7.11 | AE18: 7.275 | AF18: 0.385 | AG18: -0.002 | AH18: 2.154 | AI18: 4.296 | AK18: 0.457 | AL18: ='CF Distribution Annual NUTS2'!I22 -> 0.46696875 | AM18: Lithuania
T19: Malta | U19: 0 | V19: 0 | W19: 0 | Y19: 0 | Z19: 0 | AA19: 0 | AC19: 124.93 | AD19: 2.345 | AE19: 0 | AF19: 0 | AG19: 1.111 | AH19: 0.305 | AI19: 0.025 | AK19: 0.297 | AL19: ='CF Distribution Annual NUTS2'!I23 -> 0.306 | AM19: Malta
T20: Netherlands | U20: 0 | V20: 0 | W20: 0 | Y20: 0 | Z20: 41.675 | AA20: 6.07 | AC20: 0 | AD20: 0.035 | AE20: 73.83 | AF20: 13.005 | AG20: -0.001 | AH20: -0.002 | AI20: 9.886 | AK20: 0.469 | AL20: ='CF Distribution Annual NUTS2'!I24 -> 0.4983125 | AM20: Netherlands
T21: Poland | U21: 0 | V21: 0.21 | W21: 0 | Y21: 0 | Z21: 6.57 | AA21: 5.74 | AC21: 5.38 | AD21: 46.82 | AE21: 24.42 | AF21: 8.285 | AG21: 4.065 | AH21: 4.08 | AI21: 25.666 | AK21: 0.452 | AL21: ='CF Distribution Annual NUTS2'!I25 -> 0.4813125 | AM21: Poland
T22: Portugal | U22: 0 | V22: 0 | W22: 0 | Y22: 0 | Z22: 0 | AA22: 0.005 | AC22: 57.615 | AD22: 7.21 | AE22: 0.115 | AF22: 0 | AG22: 18.712 | AH22: 20.084 | AI22: 11.08 | AK22: 0.339 | AL22: ='CF Distribution Annual NUTS2'!I26 -> 0.38621875 | AM22: Portugal
T23: Romania | U23: 0 | V23: 0.185 | W23: 0 | Y23: 0 | Z23: 8.75 | AA23: 0.015 | AC23: 29.65 | AD23: 38.75 | AE23: 29.91 | AF23: 0 | AG23: 0.002 | AH23: 6.973 | AI23: 4.005 | AK23: 0.357 | AL23: ='CF Distribution Annual NUTS2'!I27 -> 0.38675 | AM23: Romania
T24: Spain | U24: 0 | V24: 0 | W24: 0 | Y24: 0 | Z24: 0.553 | AA24: 0.105 | AC24: 235.67265 | AD24: 18.586105 | AE24: 0.87587281 | AF24: 0.10476948 | AG24: 50.296892 | AH24: 34.126352 | AI24: 24.11039 | AK24: 0.324 | AL24: ='CF Distribution Annual NUTS2'!I29 -> 0.4643125 | AM24: Spain
T25: Sweden | U25: 0 | V25: 7.51 | W25: 3.43 | Y25: 0 | Z25: 21.05 | AA25: 9.985 | AC25: 151.895 | AD25: 106.73 | AE25: 69.715 | AF25: 17.485 | AG25: 44.787 | AH25: 74.874 | AI25: 89.061 | AK25: 0.44 | AL25: ='CF Distribution Annual NUTS2'!I30 -> 0.49725 | AM25: Sweden
T26: United Kingdom | U26: 0 | V26: 30.35 | W26: 13.555 | Y26: 0 | Z26: 56.945 | AA26: 46.66 | AC26: 968.245 | AD26: 452.515 | AE26: 128.7 | AF26: 62.115 | AG26: 153.544 | AH26: 146.31 | AI26: 96.499 | AK26: 0.486 | AL26: ='CF Distribution Annual NUTS2'!I31 -> 0.55621875 | AM26: United Kingdom
T27: EU28 | U27: =SUM(U5:U26) -> 0 | V27: =SUM(V5:V26) -> 55.381 | W27: =SUM(W5:W26) -> 24.662 | Y27: =SUM(Y5:Y26) -> 0 | Z27: =SUM(Z5:Z26) -> 227.567 | AA27: =SUM(AA5:AA26) -> 96.604 | AC27: =SUM(AC5:AC26) -> 3024.254 | AD27: =SUM(AD5:AD26) -> 1009.6615 | AE27: =SUM(AE5:AE26) -> 611.74532 | AF27: =SUM(AF5:AF26) -> 175.75245 | AG27: =SUM(AG5:AG26) -> 508.18377 | AH27: =SUM(AH5:AH26) -> 546.79484 | AI27: =SUM(AI5:AI26) -> 721.37986

Sheet OFFSHORE GIS output example
V2: Table for offshore, all wind conditions
V3: EU-Wide low restrictions
T4: [km2] | V4: Water depth 100-1000m Floating | W4: Water depth 60-100m Floating | X4: Water depth 30-60m | Y4: Water depth 0-30m | Z4: 12nm zone, water depth 60-100m Floating | AA4: 12nm zone, water depth 30-60m | AB4: 12nm zone, water depth 0-30m
T5: Belgium | V5: 0 | W5: 0 | X5: 28.8 | Y5: 32.8 | Z5: 0 | AA5: 0.2 | AB5: 308.2
T6: Bulgaria | V6: 5394 | W6: 2293.6 | X6: 265.6 | Y6: 0 | Z6: 685.4 | AA6: 2493.4 | AB6: 1344
T7: Croatia | V7: 10596 | W7: 3790.4 | X7: 4528.8 | Y7: 97.6 | Z7: 6745.6 | AA7: 6760.2 | AB7: 3193.4
T8: Cyprus | V8: 8354 | W8: 0 | X8: 0 | Y8: 0 | Z8: 456 | AA8: 420 | AB8: 408
T9: Denmark | V9: 1882 | W9: 3711.2 | X9: 16250.4 | Y9: 5798.4 | Z9: 995.8 | AA9: 1569.6 | AB9: 16873.6
T10: Estonia | V10: 1678 | W10: 1291.2 | X10: 1448.8 | Y10: 195.2 | Z10: 1722.8 | AA10: 2586.2 | AB10: 3520.8
T11: Finland | V11: 10600 | W11: 13688.8 | X11: 6695.2 | Y11: 1701.6 | Z11: 645.2 | AA11: 5994.8 | AB11: 19244.4
T12: France | V12: 81013 | W12: 17384.8 | X12: 8510.4 | Y12: 504.8 | Z12: 8902.2 | AA12: 11315.6 | AB12: 19617.2
T13: Germany | V13: 0 | W13: 0 | X13: 10606.4 | Y13: 5436 | Z13: 0 | AA13: 3.6 | AB13: 5079
T14: Greece | V14: 28872 | W14: 612 | X14: 4 | Y14: 0.8 | Z14: 15974 | AA14: 9020 | AB14: 5664.2
T15: Ireland | V15: 118487 | W15: 19611.2 | X15: 1026.4 | Y15: 0 | Z15: 11978.8 | AA15: 9092.6 | AB15: 5341
T16: Italy | V16: 65812 | W16: 4974.4 | X16: 4224 | Y16: 639.2 | Z16: 14090.6 | AA16: 11224 | AB16: 16976.8
... T26: United Kingdom | V26: 193649 | W26: 90503.2 | X26: 25740 | Y26: 12423.2 | Z26: 30708.8 | AA26: 29262 | AB26: 19299.8
T27: EU28 | V27: =SUM(V5:V26) -> 664531 | W27: =SUM(W5:W26) -> 207351.2 | X27: =SUM(X5:X26) -> 127048.8 | Y27: =SUM(Y5:Y26) -> 35496 | Z27: =SUM(Z5:Z26) -> 118652.8 | AA27: =SUM(AA5:AA26) -> 122595.2 | AB27: =SUM(AB5:AB26) -> 156541

Sheet OFFSHORE by sea basin EU27
V2: Table for offshore, all wind conditions
V3: EU-Wide low restrictions
T4: [GWe] | V4: Water depth 100-1000m Floating | W4: Water depth 60-100m Floating | X4: Water depth 30-60m | Y4: Water depth 0-30m | Z4: 12nm zone | AA4: Total
T5: North Sea, incl. the Kattegat and the English Channel | V5: =V24/1000*'Raw data'!$D$2 -> 21.064 | W5: =W24/1000*'Raw data'!$D$2 -> 9.188 | X5: =X24/1000*'Raw data'!$D$2 -> 221.504 | Y5: =Y24/1000*'Raw data'!$D$2 -> 62.608 | Z5: =Z24/1000*'Raw data'!$D$2 -> 122.36 | AA5: =SUM(V5:Z5) -> 436.724
T6: Baltic | V6: =V16/1000*'Raw data'!$D$2 -> 193.7 | W6: =W16/1000*'Raw data'!$D$2 -> 263.852 | X6: =X16/1000*'Raw data'!$D$2 -> 176.676 | Y6: =Y16/1000*'Raw data'!$D$2 -> 48.564 | Z6: =Z16/1000*'Raw data'!$D$2 -> 500.624 | AA6: =SUM(V6:Z6) -> 1183.416
T7: Atlantic Ocean (without North Sea) | V7: =V15/1000*'Raw data'!$D$2-V5 -> 891.868 | W7: =W15/1000*'Raw data'!$D$2-W5 -> 174.068 | X7: =X15/1000*'Raw data'!$D$2-X5 -> 33.372 | Y7: =Y15/1000*'Raw data'!$D$2-Y5 -> 0.552 | Z7: =Z15/1000*'Raw data'!$D$2-Z5 -> 347.156 | AA7: =SUM(V7:Z7) -> 1447.016
T8: Mediterranean Sea | V8: =V14/1000*'Raw data'!$D$2 -> 731.608 | W8: =W14/1000*'Raw data'!$D$2 -> 86.904 | X8: =X14/1000*'Raw data'!$D$2 -> 43.82 | Y8: =Y14/1000*'Raw data'!$D$2 -> 3.688 | Z8: =Z14/1000*'Raw data'!$D$2 -> 579.024 | AA8: =SUM(V8:Z8) -> 1445.044
T9: Black Sea | V9: =V17/1000*'Raw data'!$D$2 -> 45.284 | W9: =W17/1000*'Raw data'!$D$2 -> 50.216 | X9: =X17/1000*'Raw data'!$D$2 -> 31.24 | Y9: =Y17/1000*'Raw data'!$D$2 -> 0 | Z9: =Z17/1000*'Raw data'!$D$2 -> 33.544 | AA9: =SUM(V9:Z9) -> 160.284
T10: Total | V10: =SUM(V5:V9) -> 1883.524 | W10: =SUM(W5:W9) -> 584.228 | X10: =SUM(X5:X9) -> 506.612 | Y10: =SUM(Y5:Y9) -> 115.412 | Z10: =SUM(Z5:Z9) -> 1582.708
S13: ID | T13: name | V13: [km2] | W13: [km2] | X13: [km2] | Y13: [km2] | Z13: [km2]
S14: 1 | T14: Mediterranean Sea | V14: 146321.6 | W14: 17380.8 | X14: 8764 | Y14: 737.6 | Z14: 115804.8
S15: 2 | T15: North East Atlantic Ocean | V15: 182586.4 | W15: 36651.2 | X15: 50975.2 | Y15: 12632 | Z15: 93903.2
S16: 3 | T16: Baltic | V16: 38740 | W16: 52770.4 | X16: 35335.2 | Y16: 9712.8 | Z16: 100124.8
S17: 4 | T17: Black Sea | V17: 9056.8 | W17: 10043.2 | X17: 6248 | Y17: 0 | Z17: 6708.8
S18: 5 | T18: Black Sea - sea of Azov | V18: 0 | W18: 0 | X18: 0 | Y18: 0 | Z18: 0
S19: 6 | T19: Black Sea - sea of Marmara | V19: 0 | W19: 0 | X19: 0 | Y19: 0 | Z19: 0
S20: 7 | T20: Macaronesia | V20: 0 | W20: 0 | X20: 0 | Y20: 0 | Z20: 0
S21: 8 | T21: Adriatic Sea | V21: 20884.8 | W21: 8404 | X21: 8700 | Y21: 736.8 | Z21: 33896
S22: 9 | T22: Aegean-Levantine Sea | V22: 27712.8 | W22: 612 | X22: 4 | Y22: 0.8 | Z22: 25559.2
S23: 10 | T23: Bay of Biscay and the Iberian Coast | V23: 73796 | W23: 12364 | X23: 5561.6 | Y23: 107.2 | Z23: 36060.8
S24: 11 | T24: Greater North Sea, incl. the Kattegat and the English Channel | V24: 4212.8 | W24: 1837.6 | X24: 44300.8 | Y24: 12521.6 | Z24: 24472
S25: 12 | T25: Ionian Sea and the Central Mediterranean Sea | V25: 30616.8 | W25: 747.2 | X25: 51.2 | Y25: 0 | Z25: 12038.4
... S33: 20 | T33: No marine subregion assigned - outer limits of the continental shelf beyond 200 nm provided to UNCLOS by ES, FR, IE and UK | V33: 0 | W33: 0 | X33: 0 | Y33: 0 | Z33: 0

Sheet ENSPRESO vs other references
B2: For EU28/Europe, the tables below give the technical potential analyses from different references.
B3: ONSHORE
B4: Coverage | C4: References | E4: Power production [PWh] | F4: assuming 10 MW/km2
B5: EU28 | C5: JRC | D5: ENSPRESO, reference scenario and CF>25%, power density farm = 5MW/km2 | E5: 5.7 | F5: =E5*2 -> 11.4
D6: ENSPRESO, reference scenario and CF>20%, power density farm = 5MW/km2 | E6: 8.4 | F6: =E6*2 -> 16.8
D7: ENSPRESO, EU-Wide low restrictions and CF>15%, power density farm = 5MW/km2 | E7: 14.1 | F7: =E7*2 -> 28.2
C8: Other | D8: [1] Bosch et al. (85% of suitable land); 2017 | E8: 14.8
D9: [2] McKenna et al.; 2015 | E9: 15
D10: [3] Silva (EU25 + rest, <14UScent/kWh); 2016 | E10: 5.7
B11: Europe | C11: JRC | D11: ENSPRESO, high scenario and CF>15%, unpublished, power density farm = 5MW/km2 | E11: 22.7 | F11: =E11*2 -> 45.4
C12: Other | D12: [4] Eurek et al.; 2017 | E12: 21.1
D13: [5] EEA (EU-27 + NO + CH + Turkey); 2009 | E13: 45
D14: [6] Ryberg et al.; 2019 | E14: 34
D15: [7] Stetter – OECD Europe; 2012 | E15: 21.5
D16: [8] Zappa and van den Broek (EU28 + CH + NO, calculated back to 100% of suitable area starting from 6% of suitable area being 543 GW, own assumption CF=28%); 2018 | E16: 21.7
B20: OFFSHORE - Shallow and transitional (0-60 m)
B21: Coverage | C21: References | E21: Power production [PWh] | F21: assuming 10 MW/km2
B22: EU28 | C22: JRC | D22: ENSPRESO, reference scenario, fixed-bottom (0-60 m), power density farm = 5MW/km2 | E22: 1.3 | F22: =2*E22 -> 2.6
D23: ENSPRESO, EU-Wide low restrictions, fixed-bottom (0-60 m), power density farm = 5MW/km2 | E23: 8.2 | F23: =2*E23 -> 16.4
C24: Other | D24: [9] Arent et al. 0-60 m (assuming CF=50%); 2012 | E24: 5.5
D25: [13] Ruijgrok E.C.M. (Norway, the UK, the Netherlands and the North Sea EEZs of Denmark and Germany.), 0-55 m, based on roll-out of 130 GW and assuming CF=50%; 2019 | E25: 0.6
B26: Europe | C26: Other | D26: [10] Bosch et al. 0-60 m; 2018 | E26: 35.7
D27: [8] Zappa and van den Broek (EU28 + CH + NO), 0-50 m; 2018 | E27: 3.3
B31: OFFSHORE - Deep waters (60-1000 m)
B32: Coverage | C32: References | E32: Power production [PWh] | F32: assuming 10 MW/km2
B33: EU28 | C33: JRC | D33: ENSPRESO, EU-Wide low restrictions, floating (60-100 m), power density farm = 5MW/km2 | E33: 6.1 | F33: =2*E33 -> 12.2
D34: ENSPRESO, EU-Wide low restrictions, floating (60-1000 m), power density farm = 5MW/km2 | E34: 18.3 | F34: =2*E34 -> 36.6
D35: [9] Arent et al. 60-1000 m(assuming CF=50%); 2012 | E35: 12.7
B36: Europe | D36: [10] Bosch et al. 60–1000 m; 2018 | E36: 78.9
D37: [8] Zappa and van den Broek (EU28 + CH + NO), full EEZ grid; 2018 | E37: 25.9
B40: OFFSHORE - Total (no split available)
B41: Coverage | C41: References | E41: Power production [PWh] | F41: assuming 10 MW/km2
B42: EU28 | C42: JRC | D42: ENSPRESO, EU-Wide low restrictions, power density farm = 5MW/km2 | E42: =E23+E34 -> 26.5 | F42: =2*E42 -> 53
B43: Europe | D43: [11] Caglayan et al. (cut-off @70 EUR/MWh LCOE); 2019 | E43: 40
D44: [12] Wind Europe (North Sea, Baltic Sea and Atlantic Ocean from France to the Northern UK); 2017 | E44: 13
B47: References
A48: 1 | B48: J. Bosch, I. Staffell, A. D. Hawkes, Temporally-explicit and spatially-resolved global onshore wind energy potentials, Energy 131 (2017) 207–217. doi:10.1016/j.energy.2017.05.052.
A49: 2 | B49: R. McKenna, S. Hollnaicher, P. O. vd Leye, W. Fichtner, Cost-potentials for large onshore wind turbines in Europe, Energy 83 (2015) 217–229.
A50: 3 | B50: D. Silva, H. Dai, S. Fujimori, T. Masui, Global assessment of onshore wind power resources considering the distance to urban areas, Energy Policy. 91 (2016) 75–86. doi:10.1016/j.enpol.2015.12.024.
A51: 4 | B51: K. Eurek, P. Sullivan, M. Gleason, D. Hettinger, D. Heimiller, A. Lopez, An improved global wind resource estimate for integrated assessment models, Energy Economics 64 (2017) 552–567. doi:10.1016/j.eneco.2016.11.015.
...

Sheet Raw data
C2: Power density of the wind farm | D2: 5 | E2: MW/km2
F4: UNIT | I4: km2 | J4: km2 | K4: % | L4: GW | M4: GW | N4: GW | O4: GW | P4: [] | Q4: MWh/1000hab | R4: % | S4: % | T4: % | U4: % | V4: % | W4: [] | X4: [] | Y4: [] | Z4: [] | AA4: [] | AB4: [] | AC4: [] | AD4: TWh | AE4: TWh | AF4: TWh | AG4: TWh | AH4: TWh | AI4: TWh | AJ4: % | AK4: []
F5: METADATA | H5: Category | I5: Total Nuts2 area | K5: Share of surface for a particular scenarios | R5: Share of land with certain CF range | S5: Share of land with certain CF range | T5: Share of land with certain CF range | U5: Share of land with certain CF range | V5: Share of land available Wind Onshore - High wind conditions Capacity Factor > 20% for a turbine with 300 W/m2 specific power at 100m hub height | W5: Capacity Factor for particular CF range; P10 (10% best) | X5: Capacity Factor for particular CF range; 15% losses | Y5: Capacity Factor full NUTS2 with 15% losses | Z5: Capacity Factor for particular CF range; 15% losses | AA5: Capacity Factor for particular CF range; 15% losses | AB5: Capacity Factor for particular CF range; 15% losses | AC5: Capacity Factor for particular CF range; 15% losses | AD5: Power production | AE5: Power production | AF5: Power production | AG5: Power production | AH5: Power production | AI5: Electricity consumption | AJ5: TWh CF>20 divided by consumption | AK5: Number of turbines with CF>20% (10MW offshore and 3MW onshore)
A6: NUTS2Nr | B6: Nuts2 | C6: Country1 | D6: Country Code | E6: Scenario | F6: ONOFF | G6: Offshore categories | H6: Subscenario - not cumulative | I6: Nuts Area | J6: Suitable area | K6: SHARE_Surface | L6: GW_<15%_2030_100m_ALLTIMESLICESAVERAGE_V112 | M6: GW_15%-20%_2030_100m_ALLTIMESLICESAVERAGE_V112 | N6: GW_20%-25%_2030_100m_ALLTIMESLICESAVERAGE_V112 | O6: GW_Morethan25%_2030_100m_ALLTIMESLICESAVERAGE_V112 | P6: Population | Q6: MWh_TOT_Per1000hab | R6: Share lower 15% | S6: Share 15%-20% | T6: Share 20%-25% | U6: Share >25% after correction with 85% | V6: AVG([SHARE_Surface]*([Share >25% after correction with 85%]+[Share 20%-25%])) | W6: RealCF (top 10%) | X6: RealCF>20 | Y6: Real average CF over whole region | Z6: RealCF<15% | AA6: RealCF15%-20% | AB6: RealCF20%-25% | AC6: RealCF>25% | AD6: TWh_<15%_2030_100m_ALLTIMESLICESAVERAGE_V112 | AE6: TWh_15%-20%_2030_100m_ALLTIMESLICESAVERAGE_V112 | AF6: TWh_20%-25%_2030_100m_ALLTIMESLICESAVERAGE_V112 | AG6: TWh_Morethan25%_2030_100m_ALLTIMESLICESAVERAGE_V112 | AH6: TWH_>20% | AI6: CountryElec_TWh | AJ6: RatioCons | AK6: Turbines_TOT
A7: 2 | B7: AT11 | C7: Austria | D7: AT | E7: EU-Wide high restrictions | F7: Onshore | H7: 1200m setback distance | I7: 3944 | J7: 362 | K7: =J7/I7 -> 0.09178499 | L7: =R7*$J7*$D$2/1000 -> 0 | M7: =S7*$J7*$D$2/1000 -> 0.25171254 | N7: =T7*$J7*$D$2/1000 -> 0.48213097 | O7: =U7*$J7*$D$2/1000 -> 1.0761565 | P7: 290608 | Q7: 12.507074 | R7: 0 | S7: 0.1390677 | T7: 0.2663707 | U7: 0.5945616 | V7: =K7*(T7+U7) -> 0.079020662 | W7: 0.303875 | X7: 0.26626347 | Y7: =SUMPRODUCT(R7:U7,Z7:AC7) -> 0.25357167 | AA7: 0.175 | AB7: 0.225 | AC7: 0.28475 | AD7: =IFERROR(L7*Z7*8760/1000,0) -> 0 | AE7: =IFERROR(M7*AA7*8760/1000,0) -> 0.38587533 | AF7: =IFERROR(N7*AB7*8760/1000,0) -> 0.95028013 | AG7: =IFERROR(O7*AC7*8760/1000,0) -> 2.6843755 | AH7: =AF7+AG7 -> 3.6346556 | AI7: 61.851944 | AJ7: =AH7/AI7 -> 0.058763806 | AK7: =ROUND((O7+N7)/0.003,0) -> 519
A8: 3 | B8: AT12 | C8: Austria | D8: AT | E8: EU-Wide high restrictions | F8: Onshore | H8: 1200m setback distance | I8: 19185 | J8: 1644 | K8: =J8/I8 -> 0.085691947 | L8: =R8*$J8*$D$2/1000 -> 0 | M8: =S8*$J8*$D$2/1000 -> 0 | N8: =T8*$J8*$D$2/1000 -> 1.2873971 | O8: =U8*$J8*$D$2/1000 -> 6.9326029 | P8: 1652324 | Q8: 12.274766 | R8: 0 | S8: 0 | T8: 0.15661765 | U8: 0.84338235 | V8: =K8*(T8+U8) -> 0.085691947 | W8: 0.32884375 | X8: 0.28166475 | Y8: =SUMPRODUCT(R8:U8,Z8:AC8) -> 0.28166475 | AB8: 0.225 | AC8: 0.2921875 | AD8: =IFERROR(L8*Z8*8760/1000,0) -> 0 | AE8: =IFERROR(M8*AA8*8760/1000,0) -> 0 | AF8: =IFERROR(N8*AB8*8760/1000,0) -> 2.5374596 | AG8: =IFERROR(O8*AC8*8760/1000,0) -> 17.744431 | AH8: =AF8+AG8 -> 20.28189 | AI8: 61.851944 | AJ8: =AH8/AI8 -> 0.32791031 | AK8: =ROUND((O8+N8)/0.003,0) -> 2740
A9: 295 | B9: AT13 | C9: Austria | D9: AT | E9: EU-Wide high restrictions | F9: Onshore | H9: 1200m setback distance | I9: 413 | J9: 0 | K9: =J9/I9 -> 0 | L9: =R9*$J9*$D$2/1000 -> 0 | M9: =S9*$J9*$D$2/1000 -> 0 | N9: =T9*$J9*$D$2/1000 -> 0 | O9: =U9*$J9*$D$2/1000 -> 0 | P9: 1837438 | Q9: 0 | R9: 0 | S9: 0 | T9: 0 | U9: 1 | V9: =K9*(T9+U9) -> 0 | W9: 0.303875 | X9: 0.2964375 | Y9: =SUMPRODUCT(R9:U9,Z9:AC9) -> 0.2964375 | AC9: 0.2964375 | AD9: =IFERROR(L9*Z9*8760/1000,0) -> 0 | AE9: =IFERROR(M9*AA9*8760/1000,0) -> 0 | AF9: =IFERROR(N9*AB9*8760/1000,0) -> 0 | AG9: =IFERROR(O9*AC9*8760/1000,0) -> 0 | AH9: =AF9+AG9 -> 0 | AI9: 61.851944 | AJ9: =AH9/AI9 -> 0 | AK9: =ROUND((O9+N9)/0.003,0) -> 0
A10: 4 | B10: AT21 | C10: Austria | D10: AT | E10: EU-Wide high restrictions | F10: Onshore | H10: 1200m setback distance | I10: 9525 | J10: 1047 | K10: =J10/I10 -> 0.10992126 | L10: =R10*$J10*$D$2/1000 -> 2.6318228 | M10: =S10*$J10*$D$2/1000 -> 0.57769407 | N10: =T10*$J10*$D$2/1000 -> 0.5837025 | O10: =U10*$J10*$D$2/1000 -> 1.4417806 | P10: 559846 | Q10: 9.413705 | R10: 0.50273598 | S10: 0.11035226 | T10: 0.1115 | U10: 0.27541176 | V10: =K10*(T10+U10) -> 0.042529829 | W10: 0.3623125 | X10: 0.29702735 | Y10: =SUMPRODUCT(R10:U10,Z10:AC10) -> 0.18450862 | Z10: 0.1 | AA10: 0.175 | AB10: 0.225 | AC10: 0.3261875 | AD10: =IFERROR(L10*Z10*8760/1000,0) -> 2.3054768 | AE10: =IFERROR(M10*AA10*8760/1000,0) -> 0.885605 | AF10: =IFERROR(N10*AB10*8760/1000,0) -> 1.1504776 | AG10: =IFERROR(O10*AC10*8760/1000,0) -> 4.1197475 | AH10: =AF10+AG10 -> 5.2702251 | AI10: 61.851944 | AJ10: =AH10/AI10 -> 0.085207104 | AK10: =ROUND((O10+N10)/0.003,0) -> 675
A11: 5 | B11: AT22 | C11: Austria | D11: AT | E11: EU-Wide high restrictions | F11: Onshore | H11: 1200m setback distance | I11: 16436 | J11: 907 | K11: =J11/I11 -> 0.055183743 | L11: =R11*$J11*$D$2/1000 -> 1.7750113 | M11: =S11*$J11*$D$2/1000 -> 1.1529613 | N11: =T11*$J11*$D$2/1000 -> 0.50692889 | O11: =U11*$J11*$D$2/1000 -> 1.1000985 | P11: 1230756 | Q11: 3.3950012 | R11: 0.39140272 | S11: 0.25423623 | T11: 0.11178145 | U11: 0.2425796 | V11: =K11*(T11+U11) -> 0.019554969 | W11: 0.38515625 | X11: 0.29681409 | Y11: =SUMPRODUCT(R11:U11,Z11:AC11) -> 0.18881097 | Z11: 0.1 | AA11: 0.175 | AB11: 0.225 | AC11: 0.32990625 | AD11: =IFERROR(L11*Z11*8760/1000,0) -> 1.5549099 | AE11: =IFERROR(M11*AA11*8760/1000,0) -> 1.7674897 | AF11: =IFERROR(N11*AB11*8760/1000,0) -> 0.99915685 | AG11: =IFERROR(O11*AC11*8760/1000,0) -> 3.1792613 | AH11: =AF11+AG11 -> 4.1784181 | AI11: 61.851944 | AJ11: =AH11/AI11 -> 0.067555162 | AK11: =ROUND((O11+N11)/0.003,0) -> 536
A12: 6 | B12: AT31 | C12: Austria | D12: AT | E12: EU-Wide high restrictions | F12: Onshore | H12: 1200m setback distance | I12: 11967 | J12: 1021 | K12: =J12/I12 -> 0.085317958 | L12: =R12*$J12*$D$2/1000 -> 0 | M12: =S12*$J12*$D$2/1000 -> 1.2568192 | N12: =T12*$J12*$D$2/1000 -> 2.1064749 | O12: =U12*$J12*$D$2/1000 -> 1.7417059 | P12: 1451918 | Q12: 5.8295088 | R12: 0 | S12: 0.24619377 | T12: 0.41262976 | U12: 0.34117647 | V12: =K12*(T12+U12) -> 0.064313208 | W12: 0.3198125 | X12: 0.25108136 | Y12: =SUMPRODUCT(R12:U12,Z12:AC12) -> 0.23235061 | AA12: 0.175 | AB12: 0.225 | AC12: 0.282625 | AD12: =IFERROR(L12*Z12*8760/1000,0) -> 0 | AE12: =IFERROR(M12*AA12*8760/1000,0) -> 1.9267038 | AF12: =IFERROR(N12*AB12*8760/1000,0) -> 4.1518621 | AG12: =IFERROR(O12*AC12*8760/1000,0) -> 4.3121067 | AH12: =AF12+AG12 -> 8.4639688 | AI12: 61.851944 | AJ12: =AH12/AI12 -> 0.1368424 | AK12: =ROUND((O12+N12)/0.003,0) -> 1283
A13: 7 | B13: AT32 | C13: Austria | D13: AT | E13: EU-Wide high restrictions | F13: Onshore | H13: 1200m setback distance | I13: 7155 | J13: 741 | K13: =J13/I13 -> 0.10356394 | L13: =R13*$J13*$D$2/1000 -> 1.2768789 | M13: =S13*$J13*$D$2/1000 -> 0.51280277 | N13: =T13*$J13*$D$2/1000 -> 0.56940486 | O13: =U13*$J13*$D$2/1000 -> 1.3459135 | P13: 545074 | Q13: 9.0800935 | R13: 0.34463668 | S13: 0.1384083 | T13: 0.15368552 | U13: 0.36326949 | V13: =K13*(T13+U13) -> 0.053537899 | W13: 0.37878125 | X13: 0.29498553 | Y13: =SUMPRODUCT(R13:U13,Z13:AC13) -> 0.21117937 | Z13: 0.1 | AA13: 0.175 | AB13: 0.225 | AC13: 0.32459375 | AD13: =IFERROR(L13*Z13*8760/1000,0) -> 1.1185459 | AE13: =IFERROR(M13*AA13*8760/1000,0) -> 0.78612664 | AF13: =IFERROR(N13*AB13*8760/1000,0) -> 1.122297 | AG13: =IFERROR(O13*AC13*8760/1000,0) -> 3.8270259 | AH13: =AF13+AG13 -> 4.9493229 | AI13: 61.851944 | AJ13: =AH13/AI13 -> 0.080018873 | AK13: =ROUND((O13+N13)/0.003,0) -> 638
A14: 8 | B14: AT33 | C14: Austria | D14: AT | E14: EU-Wide high restrictions | F14: Onshore | H14: 1200m setback distance | I14: 12645 | J14: 1760 | K14: =J14/I14 -> 0.13918545 | L14: =R14*$J14*$D$2/1000 -> 3.3252941 | M14: =S14*$J14*$D$2/1000 -> 1.310112 | N14: =T14*$J14*$D$2/1000 -> 1.327395 | O14: =U14*$J14*$D$2/1000 -> 2.8371989 | P14: 738455 | Q14: 13.663041 | R14: 0.37787433 | S14: 0.14887637 | T14: 0.15084034 | U14: 0.32240896 | V14: =K14*(T14+U14) -> 0.065869416 | W14: 0.3516875 | X14: 0.27656337 | Y14: =SUMPRODUCT(R14:U14,Z14:AC14) -> 0.19472422 | Z14: 0.1 | AA14: 0.175 | AB14: 0.225 | AC14: 0.3006875 | AD14: =IFERROR(L14*Z14*8760/1000,0) -> 2.9129577 | AE14: =IFERROR(M14*AA14*8760/1000,0) -> 2.0084018 | AF14: =IFERROR(N14*AB14*8760/1000,0) -> 2.6162955 | AG14: =IFERROR(O14*AC14*8760/1000,0) -> 7.4732457 | AH14: =AF14+AG14 -> 10.089541 | AI14: 61.851944 | AJ14: =AH14/AI14 -> 0.16312407 | AK14: =ROUND((O14+N14)/0.003,0) -> 1388
A15: 9 | B15: AT34 | C15: Austria | D15: AT | E15: EU-Wide high restrictions | F15: Onshore | H15: 1200m setback distance | I15: 2592 | J15: 422 | K15: =J15/I15 -> 0.16280864 | L15: =R15*$J15*$D$2/1000 -> 0.71611921 | M15: =S15*$J15*$D$2/1000 -> 0.31689612 | N15: =T15*$J15*$D$2/1000 -> 0.37261702 | O15: =U15*$J15*$D$2/1000 -> 0.70436765 | P15: 383657 | Q15: 6.8612374 | R15: 0.33939299 | S15: 0.15018773 | T15: 0.17659574 | U15: 0.33382353 | V15: =K15*(T15+U15) -> 0.083100669 | W15: 0.36178125 | X15: 0.27901782 | Y15: =SUMPRODUCT(R15:U15,Z15:AC15) -> 0.20263823 | Z15: 0.1 | AA15: 0.175 | AB15: 0.225 | AC15: 0.30759375 | AD15: =IFERROR(L15*Z15*8760/1000,0) -> 0.62732043 | AE15: =IFERROR(M15*AA15*8760/1000,0) -> 0.48580175 | AF15: =IFERROR(N15*AB15*8760/1000,0) -> 0.73442815 | AG15: =IFERROR(O15*AC15*8760/1000,0) -> 1.8979336 | AH15: =AF15+AG15 -> 2.6323617 | AI15: 61.851944 | AJ15: =AH15/AI15 -> 0.042559078 | AK15: =ROUND((O15+N15)/0.003,0) -> 359
A16: 296 | B16: BE10 | C16: Belgium | D16: BE | E16: EU-Wide high restrictions | F16: Onshore | H16: 1200m setback distance | I16: 160 | J16: 0 | K16: =J16/I16 -> 0 | L16: =R16*$J16*$D$2/1000 -> 0 | M16: =S16*$J16*$D$2/1000 -> 0 | N16: =T16*$J16*$D$2/1000 -> 0 | O16: =U16*$J16*$D$2/1000 -> 0 | P16: 1201285 | Q16: 0 | R16: 0.12740642 | S16: 0.70854129 | T16: 0.16405229 | U16: 0 | V16: =K16*(T16+U16) -> 0 | W16: 0.075 | X16: 0.225 | Y16: =SUMPRODUCT(R16:U16,Z16:AC16) -> 0.17364713 | Z16: 0.1 | AA16: 0.175 | AB16: 0.225 | AD16: =IFERROR(L16*Z16*8760/1000,0) -> 0 | AE16: =IFERROR(M16*AA16*8760/1000,0) -> 0 | AF16: =IFERROR(N16*AB16*8760/1000,0) -> 0 | AG16: =IFERROR(O16*AC16*8760/1000,0) -> 0 | AH16: =AF16+AG16 -> 0 | AI16: 81.848056 | AJ16: =AH16/AI16 -> 0 | AK16: =ROUND((O16+N16)/0.003,0) -> 0
